Workbook

Sheet 计划
A1: 墨西哥CVT总成装配线MES系统 — 现场实施计划表
A2: 项目：CVT总成装配线MES系统（墨西哥） 合同编号：CDT-ZB251022-EPHOD-CVT-MES-01 甲方：重庆以弗德智能装备有限公司 乙方：上海递缇智能系统有限公司
A3: 版本 V2.3（现场实施版） 编制：上海递缇项目管理 计划开始日：见“说明与修订”页（B5，可一键联动） 现场实施：38天 远程调试：1人×1个月 试运行：3个月或1000台
A4: 阶段 | B4: 序号 | C4: 工作内容 | D4: 周期 (Day) | E4: 计划开始 | F4: 计划完成 | G4: 负责人 | H4: 责任方 | I4: 状态描述 | J4: 前置条件 / 依赖 | K4: 备注（差异与风险）
A5: 启动与前置条件确认 | B5: 1 | C5: 设备到货清关、开箱验货及IT环境确认（网段、IP、防火墙、端口、远程工具） | D5: 2 | E5: =说明与修订!$B$5+L5 -> 46328 | F5: =E5+D5-1 -> 46329 | G5: 递缇项目经理 | H5: 双方 | I5: 待客户确认 | J5: 设备到达墨西哥并完成清关，具备开箱验收条件 | K5: 扫码枪实到10把（缺5把）；一体机后到；清关由甲方负责 | L5: 0
A6: 现场硬件与网络环境搭建 | B6: 2 | C6: 服务器机柜就位，安装服务器、显示器、键鼠、UPS、交换机 | D6: 2 | E6: =说明与修订!$B$5+L6 -> 46330 | F6: =E6+D6-1 -> 46331 | G6: 以弗德安装组 | H6: 以弗德（报价含2人8天） | I6: 未开始 | J6: 机柜、服务器、UPS、交换机到位，供电正常 | K6: 交换机、一体机、扫码枪、大屏、支架、辅材由以弗德提供 | L6: 2
B7: 3 | C7: 服务器上电，检查硬件状态、硬盘、内存、网口、RAID | D7: 1 | E7: =说明与修订!$B$5+L7 -> 46332 | F7: =E7+D7-1 -> 46332 | G7: 递缇实施工程师 | H7: 递缇 | I7: 未开始 | J7: 服务器到位，供电正常 | K7: 机房接地与UPS带载需先确认 | L7: 4
B8: 4 | C8: 服务器系统与数据库复核（国内已安装）：核对主机名、固定IP、防火墙、远程桌面、实例、账号、端口、备份策略；异常时按镜像或配置基线恢复 | D8: 1 | E8: =说明与修订!$B$5+L8 -> 46333 | F8: =E8+D8-1 -> 46333 | G8: 递缇实施工程师 | H8: 递缇 | I8: 未开始 | J8: 服务器硬件自检正常；国内已完成系统与数据库安装，具备镜像或配置基线 | K8: ★国内已调过一轮，原“装Windows Server”“装SQL Server”两条合并为复核；若硬件变更再重新安装 | L8: 5
B9: 5 | C9: 配置网络交换机，划分/确认MES网段，连接服务器、工位一体机、大屏、PLC及设备 | D9: 2 | E9: =说明与修订!$B$5+L9 -> 46332 | F9: =E9+D9-1 -> 46333 | G9: 递缇实施工程师 | H9: 甲方提供交换机，双方配置 | I9: 未开始 | J9: 交换机到位，最终用户网络参数确认 | K9: 交换机为甲方供货，需甲方开放配置权限 | L9: 4
B10: 6 | C10: 安装15台工位一体机及支架，上电，配置网络 | D10: 4 | E10: =说明与修订!$B$5+L10 -> 46334 | F10: =E10+D10-1 -> 46337 | G10: 以弗德安装组 | H10: 以弗德（一体机15台已到货） | I10: 未开始 | J10: 一体机、支架到位，工位供电与网络到位 | K10: ★一体机原未发运、后补发到货，集中安装，窗口后移 | L10: 6
B11: 7 | C11: 安装并调试扫码枪：到场10把有线/无线连接、扫码识别、条码类型；缺口5把按借用/串口枪/补发处置 | D11: 3 | E11: =说明与修订!$B$5+L11 -> 46336 | F11: =E11+D11-1 -> 46338 | G11: 递缇实施工程师 | H11: 递缇+甲方 | I11: 待客户确认 | J11: 扫码枪到位，工位一体机系统就绪 | K11: ★实到10把，缺5把；斑马清关受阻，建议递缇人员随行带1把串口枪，其余向其他工位借用或本地采购 | L11: 8
B12: 8 | C12: 安装75寸大屏电视+盒式PC，配置浏览器、网络、看板显示 | D12: 1 | E12: =说明与修订!$B$5+L12 -> 46338 | F12: =E12+D12-1 -> 46338 | G12: 以弗德安装组 | H12: 以弗德 | I12: 未开始 | J12: 大屏、盒式PC到位，网络连通 | L12: 10
B13: 9 | C13: 检查桥架、网线、电源线等安装辅材，确认工位网络与供电稳定 | D13: 2 | E13: =说明与修订!$B$5+L13 -> 46333 | F13: =E13+D13-1 -> 46334 | G13: 以弗德安装组 | H13: 以弗德 | I13: 未开始 | J13: 辅材到位，现场施工完成 | L13: 5
A14: MES软件部署与基础配置 | B14: 10 | C14: 部署MES服务端：软件包、组件、依赖环境，初始化数据库 | D14: 2 | E14: =说明与修订!$B$5+L14 -> 46340 | F14: =E14+D14-1 -> 46341 | G14: 递缇实施工程师 | H14: 递缇 | I14: 未开始 | J14: 服务器系统、SQL Server就绪 | L14: 12
B15: 11 | C15: 部署工控机客户端到15个工位一体机，配置启动项、客户端参数 | D15: 2 | E15: =说明与修订!$B$5+L15 -> 46340 | F15: =E15+D15-1 -> 46341 | G15: 递缇实施工程师 | H15: 递缇 | I15: 未开始 | J15: 工位一体机系统与网络就绪 | K15: 一体机后到货，客户端镜像建议用同型号测试机提前验证 | L15: 12
B16: 12 | C16: 基础数据与工艺建模（一次性完成）：系统语言中/西切换、用户/角色/权限/员工与工位技能；主动轮、从动轮产品型号与工艺参数（组件、厂商、重量/扭力/动平衡上下限）；工艺路线、工序、15工位启用与干涉跳过；电子作业指导（PDM图、预装提示、按车型切换）；拧紧工艺配方（枪、程序号、数量、不合格次数、使能） | D16: 3 | E16: =说明与修订!$B$5+L16 -> 46342 | F16: =E16+D16-1 -> 46344 | G16: 递缇实施工程师 | H16: 递缇 | I16: 未开始 | J16: MES服务端部署完成；甲方提供组织架构、主动轮/从动轮工艺参数、PDM图与作业指导书 | K16: 原6条（语言/权限/主动轮/从动轮/工艺路线/ESOP/拧紧）合并为1个工作包，按产品型号整体建模、一次校验 | L16: 14
B17: 13 | C17: 业务规则与报表看板配置：条码规则与标签模板、上线打印；订单管理（生产计划、工单、编号规则、终端客户）；质量报表、SPC、电子看板、日志与追溯；MES-SAP/PLC 预留接口 | D17: 2 | E17: =说明与修订!$B$5+L17 -> 46345 | F17: =E17+D17-1 -> 46346 | G17: 递缇实施工程师 | H17: 递缇 | I17: 未开始 | J17: 基础数据与工艺建模完成；条码规则、报表格式、看板内容确认 | K17: 原5条（条码规则/订单/报表/看板/预留接口）合并；报表与看板样式需甲方确认 | L17: 17
B18: 14 | C18: 上线打码/标签打印统一调试（全部硬件上电、标签模板配置完成后进行）：标签模板、条码规则、总成二维码打印 | D18: 1 | E18: =说明与修订!$B$5+L18 -> 46347 | F18: =E18+D18-1 -> 46347 | G18: 递缇实施工程师 | H18: 甲方提供打码设备 | I18: 待客户确认 | J18: 一体机、扫码枪、大屏全部上电且网络连通；打码设备到位、标签模板配置完成 | K18: ★独立保留：依赖硬件上电与甲方打码设备，不并入配置包；合同仅含标签打印与条码规则 | L18: 19
B19: 15 | C19: 配置设备采集接口：伺服压机5台、ATLAS拧紧枪1把、检测设备2台、PLC四类信号通讯参数 | D19: 2 | E19: =说明与修订!$B$5+L19 -> 46348 | F19: =E19+D19-1 -> 46349 | G19: 递缇实施工程师 | H19: 递缇 | I19: 未开始 | J19: 设备接口协议、数据字典与通讯参数确认 | K19: ★独立保留：依赖设备协议，协议缺失即转为遗留项；压机5台仅国内调试 | L19: 20
A20: 工位单机与设备采集调试 | B20: 16 | C20: 服务器本地功能验证：登录、订单、工艺、报表、追溯、用户权限、日志 | D20: 1 | E20: =说明与修订!$B$5+L20 -> 46350 | F20: =E20+D20-1 -> 46350 | G20: 递缇实施工程师 | H20: 递缇 | I20: 未开始 | J20: 基础配置完成 | L20: 22
B21: 17 | C21: 逐工位验证客户端：启动、扫码、SOP显示、防错、过站、数据上传 | D21: 2 | E21: =说明与修订!$B$5+L21 -> 46351 | F21: =E21+D21-1 -> 46352 | G21: 递缇实施工程师 | H21: 递缇 | I21: 未开始 | J21: 工位客户端部署完成，网络连通 | K21: 缺枪工位先用手工录入模式，签认表标注 | L21: 23
B22: 18 | C22: 上线打码/条码绑定测试：总成二维码生成、打印、扫描、绑定 | D22: 1 | E22: =说明与修订!$B$5+L22 -> 46351 | F22: =E22+D22-1 -> 46351 | G22: 递缇实施工程师 | H22: 双方 | I22: 未开始 | J22: 打码设备、扫码枪就绪 | L22: 23
B23: 19 | C23: 零件条码采集测试：零件二维码、批次码、重复校验、数量校验、特征码校验 | D23: 1 | E23: =说明与修订!$B$5+L23 -> 46352 | F23: =E23+D23-1 -> 46352 | G23: 递缇实施工程师 | H23: 递缇 | I23: 未开始 | J23: 零件条码规则确认，扫码枪就绪 | K23: ★缺5把扫码枪的工位无法完成条码防错验证 | L23: 24
B24: 20 | C24: 过程数据采集测试：进站、出站、过站信息、工单号、序列号、工站、人员、时间 | D24: 1 | E24: =说明与修订!$B$5+L24 -> 46353 | F24: =E24+D24-1 -> 46353 | G24: 递缇实施工程师 | H24: 递缇 | I24: 未开始 | J24: 工位客户端与PLC通讯正常 | L24: 25
B25: 21 | C25: 拧紧数据采集测试：扭矩、角度、曲线、合格状态、螺栓遗漏查询 | D25: 1 | E25: =说明与修订!$B$5+L25 -> 46354 | F25: =E25+D25-1 -> 46354 | G25: 递缇实施工程师 | H25: 递缇 | I25: 未开始 | J25: 拧紧枪通讯正常，程序号配置完成 | K25: ATLAS 1把（主动轮） | L25: 26
B26: 22 | C26: 伺服压机数据采集验证：压力、位移、通讯稳定性、数据上传 | D26: 2 | E26: =说明与修订!$B$5+L26 -> 46354 | F26: =E26+D26-1 -> 46355 | G26: 甲方/设备商主责，递缇远程协助 | H26: 甲方/设备商 | I26: 待客户确认 | J26: 压机通电、网络连通、接口协议开放 | K26: ★报价明确5台压机仅国内调试、不含国外调试费用，现场责任界面需书面确认 | L26: 26
B27: 23 | C27: 检测设备数据采集验证：2台检测设备数据上传、结果绑定 | D27: 1 | E27: =说明与修订!$B$5+L27 -> 46355 | F27: =E27+D27-1 -> 46355 | G27: 递缇实施工程师 | H27: 递缇 | I27: 未开始 | J27: 检测设备接口开放、通讯正常 | L27: 27
B28: 24 | C28: 电子看板验证：订单内容、计划产量、实际产量、不良率、工位状态、SPC图 | D28: 1 | E28: =说明与修订!$B$5+L28 -> 46356 | F28: =E28+D28-1 -> 46356 | G28: 递缇实施工程师 | H28: 递缇 | I28: 未开始 | J28: 看板数据源配置完成，大屏就绪 | L28: 28
B29: 25 | C29: 质量报告与追溯验证：正反向追溯、树形展示、报表导出Excel、工号姓名显示 | D29: 1 | E29: =说明与修订!$B$5+L29 -> 46356 | F29: =E29+D29-1 -> 46356 | G29: 递缇实施工程师 | H29: 递缇 | I29: 未开始 | J29: 质量数据采集完成 | L29: 28
B30: 26 | C30: 性能验证：操作延时≤1秒、数据库查询≤4秒、并发访问、故障恢复、数据不丢失 | D30: 1 | E30: =说明与修订!$B$5+L30 -> 46357 | F30: =E30+D30-1 -> 46357 | G30: 递缇实施工程师 | H30: 递缇 | I30: 未开始 | J30: 系统稳定运行，测试数据准备 | K30: 判定方法需双方事先约定 | L30: 29
A31: 全线联调与试生产 | B31: 27 | C31: MES与PLC联调：工件到位、保存数据、保存完成、验证完成、设备监控、生产控制 | D31: 2 | E31: =说明与修订!$B$5+L31 -> 46358 | F31: =E31+D31-1 -> 46359 | G31: 递缇实施工程师 | H31: 双方 | I31: 未开始 | J31: 单机调试完成，PLC通讯正常 | L31: 30
B32: 28 | C32: MES与工厂MES/SAP接口联调（如有） | D32: 1 | E32: =说明与修订!$B$5+L32 -> 46359 | F32: =E32+D32-1 -> 46359 | G32: 递缇实施工程师 | H32: 双方 | I32: 未开始 | J32: 工厂MES/SAP接口可用 | K32: 甲方系统不具备时列为遗留项 | L32: 31
B33: 29 | C33: 全线空运行：订单下发→打码→扫码→装配→数据采集→过站→下线→追溯 | D33: 1 | E33: =说明与修订!$B$5+L33 -> 46360 | F33: =E33+D33-1 -> 46360 | G33: 双方 | H33: 双方 | I33: 未开始 | J33: 各工位、设备、PLC联调完成 | L33: 32
B34: 30 | C34: 带产品试生产：小批量验证，记录MES问题、设备采集问题、网络问题 | D34: 2 | E34: =说明与修订!$B$5+L34 -> 46361 | F34: =E34+D34-1 -> 46362 | G34: 双方 | H34: 双方 | I34: 未开始 | J34: 空运行无重大异常，试生产物料准备 | K34: 试生产物料由甲方准备 | L34: 33
B35: 31 | C35: 异常场景测试：设备异常、质量异常、数据异常、安灯报警、不合格拦截、高权限跳站 | D35: 1 | E35: =说明与修订!$B$5+L35 -> 46361 | F35: =E35+D35-1 -> 46361 | G35: 递缇实施工程师 | H35: 递缇 | I35: 未开始 | J35: 异常处理逻辑配置完成 | L35: 33
B36: 32 | C36: 生产报表、SPC、看板、日志、用户权限综合验证 | D36: 1 | E36: =说明与修订!$B$5+L36 -> 46363 | F36: =E36+D36-1 -> 46363 | G36: 递缇实施工程师 | H36: 递缇 | I36: 未开始 | J36: 试生产数据积累 | L36: 35
B37: 33 | C37: 分角色培训：操作工、班组长、质量、维护，并交付用户操作手册 | D37: 2 | E37: =说明与修订!$B$5+L37 -> 46363 | F37: =E37+D37-1 -> 46364 | G37: 递缇实施工程师 | H37: 递缇 | I37: 未开始 | J37: 系统功能验证完成 | K37: ★原计划缺培训任务，按交付物要求补充 | L37: 35
B38: 34 | C38: 预验收：按技术协议在杭州国内工厂进行；如已完成则做资料归档与遗留项确认 | D38: 1 | E38: =说明与修订!$B$5+L38 -> 46364 | F38: =E38+D38-1 -> 46364 | G38: 双方 | H38: 双方 | I38: 待确认 | J38: 杭州阶段单机部署完成 | K38: ★需确认预验收是否已随一体机后到而顺延 | L38: 36
B39: 35 | C39: 现场实施完成确认与交接：遗留问题清单、备件与工具移交 | D39: 1 | E39: =说明与修订!$B$5+L39 -> 46365 | F39: =E39+D39-1 -> 46365 | G39: 递缇项目经理 | H39: 双方 | I39: 未开始 | J39: 试生产与培训完成 | L39: 37
A40: 试运行、验收与运维 | B40: 36 | C40: 远程调试：缺陷修复、参数优化、陪产支持（1人1个月） | D40: 20 | E40: =说明与修订!$B$5+L40 -> 46366 | F40: =E40+D40-1 -> 46385 | G40: 递缇实施工程师 | H40: 递缇（报价含1人1个月） | I40: 未开始 | J40: 现场交接完成，远程通道可用 | K40: 按墨西哥时差排班 | L40: 38
...

Sheet 甘特（周）
A1: 现场实施甘特（周）｜D1 = 计划开始日
A2: 序号 | B2: 阶段 | C2: 工作内容 | D2: 周期 | E2: =TEXT(说明与修订!$B$5+7*0,"mm/dd") -> 11/02 | F2: =TEXT(说明与修订!$B$5+7*1,"mm/dd") -> 11/09 | G2: =TEXT(说明与修订!$B$5+7*2,"mm/dd") -> 11/16 | H2: =TEXT(说明与修订!$B$5+7*3,"mm/dd") -> 11/23 | I2: =TEXT(说明与修订!$B$5+7*4,"mm/dd") -> 11/30 | J2: =TEXT(说明与修订!$B$5+7*5,"mm/dd") -> 12/07 | K2: =TEXT(说明与修订!$B$5+7*6,"mm/dd") -> 12/14 | L2: =TEXT(说明与修订!$B$5+7*7,"mm/dd") -> 12/21 | M2: =TEXT(说明与修订!$B$5+7*8,"mm/dd") -> 12/28 | N2: =TEXT(说明与修订!$B$5+7*9,"mm/dd") -> 01/04 | O2: =TEXT(说明与修订!$B$5+7*10,"mm/dd") -> 01/11 | P2: =TEXT(说明与修订!$B$5+7*11,"mm/dd") -> 01/18 | Q2: =TEXT(说明与修订!$B$5+7*12,"mm/dd") -> 01/25 | R2: =TEXT(说明与修订!$B$5+7*13,"mm/dd") -> 02/01 | S2: =TEXT(说明与修订!$B$5+7*14,"mm/dd") -> 02/08 | T2: =TEXT(说明与修订!$B$5+7*15,"mm/dd") -> 02/15 | U2: =TEXT(说明与修订!$B$5+7*16,"mm/dd") -> 02/22 | V2: =TEXT(说明与修订!$B$5+7*17,"mm/dd") -> 03/01 | W2: =TEXT(说明与修订!$B$5+7*18,"mm/dd") -> 03/08 | X2: =TEXT(说明与修订!$B$5+7*19,"mm/dd") -> 03/15
A3: 1 | B3: 启动与前置条件确认 | C3: 设备到货清关、开箱验货及IT环境确认（网段、IP、防火墙、端口、远程工具） | D3: 2
A4: 2 | B4: 现场硬件与网络环境搭建 | C4: 服务器机柜就位，安装服务器、显示器、键鼠、UPS、交换机 | D4: 2
A5: 3 | B5: 现场硬件与网络环境搭建 | C5: 服务器上电，检查硬件状态、硬盘、内存、网口、RAID | D5: 1
A6: 4 | B6: 现场硬件与网络环境搭建 | C6: 服务器系统与数据库复核（国内已安装）：核对主机名、固定IP、防火墙、远程桌面、实例、账号、端口、备份策略；异常时按镜像或配置基线恢复 | D6: 1
A7: 5 | B7: 现场硬件与网络环境搭建 | C7: 配置网络交换机，划分/确认MES网段，连接服务器、工位一体机、大屏、PLC及设备 | D7: 2
A8: 6 | B8: 现场硬件与网络环境搭建 | C8: 安装15台工位一体机及支架，上电，配置网络 | D8: 4
A9: 7 | B9: 现场硬件与网络环境搭建 | C9: 安装并调试扫码枪：到场10把有线/无线连接、扫码识别、条码类型；缺口5把按借用/串口枪/补发处置 | D9: 3
A10: 8 | B10: 现场硬件与网络环境搭建 | C10: 安装75寸大屏电视+盒式PC，配置浏览器、网络、看板显示 | D10: 1
A11: 9 | B11: 现场硬件与网络环境搭建 | C11: 检查桥架、网线、电源线等安装辅材，确认工位网络与供电稳定 | D11: 2
A12: 10 | B12: MES软件部署与基础配置 | C12: 部署MES服务端：软件包、组件、依赖环境，初始化数据库 | D12: 2
A13: 11 | B13: MES软件部署与基础配置 | C13: 部署工控机客户端到15个工位一体机，配置启动项、客户端参数 | D13: 2
A14: 12 | B14: MES软件部署与基础配置 | C14: 基础数据与工艺建模（一次性完成）：系统语言中/西切换、用户/角色/权限/员工与工位技能；主动轮、从动轮产品型号与工艺参数（组件、厂商、重量/扭力/动平衡上下限）；工艺路线、工序、15工位启用与干涉跳过；电子作业指导（PDM图、预装提示、按车型切换）；拧紧工艺配方（枪、程序号、数量、不合格次数、使能） | D14: 3
... A40: 38 | B40: 试运行、验收与运维 | C40: 终验收：按技术协议逐项验收 | D40: 1
A42: 注：色块对应阶段，明细见“计划”页；质保期1年另计。

Sheet 工位签认表
A1: 15工位安装 / 上电 / 客户端 / 扫码 逐站签认表（★W11–W15 扫码枪缺口）
A2: 工位 | B2: 一体机到货 | C2: 支架安装 | D2: 上电 | E2: 网络 | F2: 客户端 | G2: 扫码枪状态 | H2: ESOP | I2: 扫码/手工录入 | J2: 签认人 | K2: 日期
A3: W01 | B3: □ | C3: □ | D3: □ | E3: □ | F3: □ | G3: 已到货 | H3: □ | I3: 扫码
A4: W02 | B4: □ | C4: □ | D4: □ | E4: □ | F4: □ | G4: 已到货 | H4: □ | I4: 扫码
A5: W03 | B5: □ | C5: □ | D5: □ | E5: □ | F5: □ | G5: 已到货 | H5: □ | I5: 扫码
A6: W04 | B6: □ | C6: □ | D6: □ | E6: □ | F6: □ | G6: 已到货 | H6: □ | I6: 扫码
A7: W05 | B7: □ | C7: □ | D7: □ | E7: □ | F7: □ | G7: 已到货 | H7: □ | I7: 扫码
A8: W06 | B8: □ | C8: □ | D8: □ | E8: □ | F8: □ | G8: 已到货 | H8: □ | I8: 扫码
A9: W07 | B9: □ | C9: □ | D9: □ | E9: □ | F9: □ | G9: 已到货 | H9: □ | I9: 扫码
A10: W08 | B10: □ | C10: □ | D10: □ | E10: □ | F10: □ | G10: 已到货 | H10: □ | I10: 扫码
A11: W09 | B11: □ | C11: □ | D11: □ | E11: □ | F11: □ | G11: 已到货 | H11: □ | I11: 扫码
A12: W10 | B12: □ | C12: □ | D12: □ | E12: □ | F12: □ | G12: 已到货 | H12: □ | I12: 扫码
A13: W11 | B13: □ | C13: □ | D13: □ | E13: □ | F13: □ | G13: 缺（借用/串口/补发） | H13: □ | I13: 手工录入
A14: W12 | B14: □ | C14: □ | D14: □ | E14: □ | F14: □ | G14: 缺（借用/串口/补发） | H14: □ | I14: 手工录入
... A17: W15 | B17: □ | C17: □ | D17: □ | E17: □ | F17: □ | G17: 缺（借用/串口/补发） | H17: □ | I17: 手工录入
A19: 说明：扫码枪实到10把；缺口5把按“借用其他工位/递缇随行带1把串口枪（RS232直连一体机COM口）/本地采购或国内补发”处置。缺枪工位先以手工录入序列号＋双人复核上线，扫码枪到位后仅改配置，无需二次开发。

Sheet 硬件清单
A1: 硬件与软件清单（含供货方、到货状态）
A2: 序号 | B2: 名称 | C2: 内容 | D2: 品牌 | E2: 单位 | F2: 数量 | G2: 提供方 | H2: 到货状态 | I2: 备注
A3: 一 | B3: 机房硬件服务器设备
A4: 1 | B4: 塔式服务器 | C4: 联想（Lenovo）塔式服务器至强E2224G 32G内存丨256G固态+2*1TSATA硬盘 | D4: Lenovo | E4: 台 | F4: 1 | G4: 递缇 | H4: 待清点
A5: 2 | B5: 显示器及键鼠 | C5: 21寸 | D5: 三星 | E5: 台 | F5: 1 | G5: 递缇 | H5: 待清点
A6: 3 | B6: 数据库软件 | C6: SQL Server 2012 R2/2016及以上 | D6: 微软 | E6: 套 | F6: 1 | G6: 递缇 | H6: 待清点
A7: 4 | B7: 操作系统 | C7: Windows Server 2016 | D7: 微软 | E7: 套 | F7: 1 | G7: 递缇 | H7: 待清点
A8: 5 | B8: 服务器机柜 | C8: 42U服务器机柜，600*600*2000 | D8: 图腾 | E8: 台 | F8: 1 | G8: 递缇 | H8: 待清点
A9: 6 | B9: 网络交换机 | C9: 24口千兆以太网+4千兆光纤口网络 | D9: 华为 | E9: 台 | F9: 1 | G9: 重庆以弗德 | H9: 待清点 | I9: 需甲方开放配置权限
A10: 7 | B10: UPS电源 | C10: 3KVA | D10: APC/SANTAK | E10: 台 | F10: 1 | G10: 递缇 | H10: 待清点
A11: 二 | B11: 现场硬件设备
A12: 1 | B12: 作业指导显示工位
A13: 1.1 | B13: 工位一体机 | C13: PPC-3321QK-HR，J6412/8G内存/256G SSD/3*RS232/2*USB/Lan*2/无风扇/win10 Iot | D13: 华北工控 | E13: 台 | F13: 15 | G13: 重庆以弗德 | H13: 已到货（晚到） | I13: ★原未发运后补发，集中安装
A14: 2 | B14: 扫码枪 | C14: DS8178-DP/USB口 有线/无线二维码扫描枪 | D14: 斑马 | E14: 台 | F14: 15 | G14: 重庆以弗德 | H14: 10把（缺5把） | I14: ★缺口5把：借用/串口枪/补发
A15: 4 | B15: 工位显示大屏幕 | C15: 75寸电视+盒式PC | D15: 小米 | E15: 台 | F15: 1 | G15: 重庆以弗德 | H15: 待清点
A16: 5 | B16: 一体机安装支架 | C16: 定制一体机安装支架 | E16: 台 | F16: 15 | G16: 重庆以弗德 | H16: 待清点
A17: 6 | B17: 设备安装辅材 | C17: 桥架，网线，电源线等 | E17: 套 | F17: 15 | G17: 重庆以弗德 | H17: 待清点
A18: 三 | B18: 软件模块
A19: 1 | B19: 订单管理 | C19: 生产订单管理、计划排产、生产执行、生产报工管理 | E19: 套 | F19: 1 | G19: 递缇 | H19: —
A20: 2 | B20: 上线打印功能 | C20: 标签打印，条码规则管理 | E20: 套 | F20: 1 | G20: 递缇 | H20: — | I20: 打码硬件不在供货清单
A21: 3 | B21: 零件条码采集 | C21: 零件条码识别，零件条码绑定 | E21: 套 | F21: 1 | G21: 递缇 | H21: —
A22: 4 | B22: 过程数据管理 | C22: 产品进站数据，出站数据采集 | E22: 套 | F22: 1 | G22: 递缇 | H22: —
A23: 5 | B23: 工艺管理 | C23: 工艺信息配置、操作工序管理 | E23: 套 | F23: 1 | G23: 递缇 | H23: —
A24: 6 | B24: 质量报告管理 | C24: 生产质量数据报告 | E24: 套 | F24: 1 | G24: 递缇 | H24: —
A25: 7 | B25: 电子看板 | C25: 产量统计，质量看板，合格率 | E25: 套 | F25: 1 | G25: 递缇 | H25: —
A26: 8 | B26: 统计分析模块 | C26: 合格率统计，生产数据统计报表 | E26: 套 | F26: 1 | G26: 递缇 | H26: —
A27: 9 | B27: 设备数据采集模块 | E27: 套 | F27: 1 | G27: 递缇 | H27: —
A28: 9.1 | B28: 与伺服压机通讯接口 | C28: 伺服压机数据采集 | E28: 套 | F28: 5 | G28: 递缇 | H28: — | I28: ★5台，CVT二线；国内调试，不含国外调试费用
A29: 9.2 | B29: 拧紧控制 | C29: 1套拧紧工具的数据采集 | E29: 套 | F29: 1 | G29: 递缇 | H29: — | I29: ATLAS拧紧枪（主动轮）
A30: 9.3 | B30: 电子操作指导 | C30: 工艺电子操作指导 | E30: 套 | F30: 1 | G30: 递缇 | H30: —
A31: 9.4 | B31: 与检测设备通讯接口 | C31: 检测设备数据采集 | E31: 套 | F31: 2 | G31: 递缇 | H31: —

Sheet 说明与修订
A1: 墨西哥CVT总成装配线MES系统 — 现场实施计划（说明与修订）
A3: 一、基线参数
A4: 参数 | B4: 值 | C4: 说明
A5: 计划开始日 | B5: 46328 | C5: ★修改此格，计划页所有日期与甘特周次自动联动
A6: 现场实施周期（自然日） | B6: =MAX(计划!F5:F39)-MIN(计划!E5:E39)+1 -> 38 | C6: 到货清点至现场交接（含并行作业）
A7: 试运行周期（自然日） | B7: 90 | C7: 生产3个月或1000台，以先到为准
A8: 远程调试投入 | B8: 1人×1个月 | C8: 报价已含
A10: 二、关键里程碑
A11: 里程碑 | B11: 计划日期 | C11: 判定标准
A12: 到货清点完成 | B12: =计划!F5 -> 46329 | C12: 开箱验货单签认
A13: 机房上电完成 | B13: =计划!F7 -> 46332 | C13: 服务器自检通过
A14: 15工位客户端就绪 | B14: =计划!F15 -> 46341 | C14: 15台可登录
A15: MES配置完成 | B15: =计划!F19 -> 46349 | C15: 基础数据、业务规则与接口配置完成
A16: 单机与采集调试完成 | B16: =计划!F30 -> 46357 | C16: 采集数据入库
A17: 试生产完成 | B17: =计划!F34 -> 46362 | C17: 问题清单闭环
A18: 现场交接 | B18: =计划!F39 -> 46365 | C18: 完成确认书签署
A19: 终验收 | B19: =计划!F42 -> 46456 | C19: 按技术协议逐项
A21: 三、对原表格已填内容的修订（逐条）
A22: 序号 | B22: 原内容 / 问题 | C22: 修订
A23: 1 | B23: “安装15把扫码枪、调试有线/无线连接” | C23: 实到10把，缺5把：改为“10把安装调试＋5把缺口处置（借用/串口枪/补发）”，并标“待客户确认”
A24: 2 | B24: “安装15台一体机及支架” | C24: 一体机原未发运、后补发：改为“集中安装”，安装窗口后移，前置条件加“到货时间确认”
A25: 3 | B25: “伺服压机数据采集验证”未注范围 | C25: 报价明确5台压机“国内调试，不含国外调试费用”：责任方改为甲方/设备商主责，递缇远程协助
A26: 4 | B26: “安装上线打印/打码设备” | C26: 合同仅含“标签打印、条码规则管理”，打码硬件未在供货清单：改为“硬件全部上电后统一调试”，设备由甲方提供
A27: 5 | B27: 无培训任务 | C27: 按交付物要求补充“分角色培训＋《用户操作手册》”，2天
A28: 6 | B28: 无预验收/终验收/质保节点 | C28: 补充预验收（杭州）、终验收、质保与7×24运维，共3条
A29: 7 | B29: 无文档交付对应 | C29: 文档按合同交付物清单单独提交（《项目实施方案》《系统需求报告》《蓝图设计》《详细设计方案》《实施报告》《培训计划》《用户操作手册》《系统上线报告》《安装配置维护手册》《预验收/终验收报告》《运行/运维报告》），计划页不再单列
A30: 8 | B30: “周期（Day）”整列空白 | C30: 全部补齐：现场实施38天（含并行），远程调试20天，试运行90天
A31: 9 | B31: “负责人”整列空白 | C31: 按角色补齐：递缇项目经理/实施工程师、以弗德安装组、甲方设备商
A32: 10 | B32: 状态描述仅“待对接” | C32: 统一状态字典并加下拉：未开始/进行中/已完成/受阻/待客户确认/待确认
A33: 11 | B33: 无责任边界 | C33: 新增“责任方”列：交换机与安装由甲方（以弗德），软件与远程调试由递缇
A34: 12 | B34: 无远程调试任务 | C34: 补为独立任务：1人1个月，与试运行并行
... A40: 18 | B40: 基础配置拆成 11 条（语言、权限、主动轮、从动轮、条码、工艺路线、ESOP、拧紧、接口、订单、报表） | C40: 按MES实施惯例合并为2个工作包：①基础数据与工艺建模3天 ②业务规则与报表看板2天；打码联调、设备采集接口因外部依赖独立保留
A42: 四、待客户确认事项（影响工期与验收）
A43: 1. 5把扫码枪的补齐责任与时间：是否同意“借用＋串口枪＋手工录入”临时方案
A44: 2. 缺枪工位优先级：哪5个工位可暂缓启用扫码防错
A45: 3. 递缇人员赴墨西哥的签证与差旅费用归属（报价仅含远程调试1人1个月）
A46: 4. 5台伺服压机国外调试界面：合同不含，是否由甲方/设备商负责，递缇仅远程协助
A47: 5. 上线打码设备由谁提供、到场时间
A48: 6. 预验收是否已在杭州完成；一体机后到货是否需补做
A49: 7. 现场网络与VPN开放时间、服务器与交换机到场时间
...
